<?xml version="1.0" encoding="UTF-8"?>
<robot name="rb1">


<gazebo reference="base_link">
  <material>Gazebo/Black</material>
</gazebo>

<gazebo reference="joint_chassis_front_caster_wheel">
    <preserveFixedJoint>true</preserveFixedJoint>
</gazebo>

<gazebo reference="joint_chassis_back_caster_wheel">
    <preserveFixedJoint>true</preserveFixedJoint>
</gazebo>

<gazebo reference="link_front_caster_wheel">
    <material>Gazebo/Grey</material>
    <mu1>0</mu1>
    <mu2>0</mu2>
</gazebo>

<gazebo reference="link_back_caster_wheel">
    <material>Gazebo/Grey</material>
    <mu1>0</mu1>
    <mu2>0</mu2>
</gazebo>

<gazebo reference="link_right_wheel">
    <material>Gazebo/Black</material>
    <mu1>1</mu1>
    <mu2>1</mu2>
</gazebo>

<gazebo reference="link_left_wheel">
    <material>Gazebo/Black</material>
    <mu1>1</mu1>
    <mu2>1</mu2>
</gazebo>

<!-- Base Footprint at the bottom center of the base cylinder -->
<link name="base_footprint">
</link>

<!-- Base Link -->

<link name="base_link">
        <visual>
            <origin xyz="0 0 0" rpy="0 0 0"/>
            <geometry>
                <cylinder length="0.30" radius="0.25"/>
            </geometry>
            <material name="Black">
              <color rgba="0 0 0 1" />
            </material>
        </visual>
        <collision>
            <origin xyz="0 0 0" rpy="0 0 0"/>
            <geometry>
                <cylinder length="0.30" radius="0.25"/>
            </geometry>
        </collision>
        <inertial>
            <origin xyz="0 0 0" rpy="0 0 0"/>
            <mass value="25"/>
            <inertia ixx="1.5625" ixy="0" ixz="0" iyy="1.5625" iyz="0" izz="0.625"/>
        </inertial>
    </link>




<!-- Joint connecting base_footprint and base_link -->
<joint name="base_joint" type="fixed">
    <parent link="base_footprint"/>
    <child link="base_link"/>
    <origin xyz="0 0 0.15" rpy="0 0 0"/> <!-- Positioned at the rotation axis -->
</joint>

  <!-- Wheels Links -->


  <!-- Joint - chassis / left wheel -->
<joint name="joint_chassis_left_wheel" type="continuous">
        <parent link="base_link"/>
        <child link="link_left_wheel"/>
        <origin xyz="0 0.25 -0.15" rpy="0 0 0"/>
        <axis xyz="0 1 0"/>
    </joint>

<!-- Link - left wheel -->

<link name="link_left_wheel">
        <inertial>
            <origin xyz="0 0 0" rpy="0 0 0"/>
            <mass value="1"/>
            <inertia ixx="0.0125" ixy="0" ixz="0" iyy="0.0125" iyz="0" izz="0.025"/>
        </inertial>
        <!-- Tires -->
        <visual>
            <origin xyz="0 0 0" rpy="1.5708 0 0"/> 
            <geometry>
                <cylinder length="0.03" radius="0.03125"/> <!-- radious a little bit bigger to preserve the radious of the caster wheels -->
            </geometry>
            <material name="Red">
             <color rgba="1 0 0 1" />
            </material>
        </visual>
        <collision>
            <origin xyz="0 0 0" rpy="1.5708 0 0"/> 
            <geometry>
                <cylinder length="0.03" radius="0.03125"/>
            </geometry>
        </collision>

    </link>

<!-- Joint - chassis / right wheel with corrected joint_properties -->
 <joint name="joint_chassis_right_wheel" type="continuous">
        <parent link="base_link"/>
        <child link="link_right_wheel"/>
        <origin xyz="0 -0.25 -0.15" rpy="0 0 0"/>
        <axis xyz="0 1 0"/>

    </joint>

<!-- Link - right wheel -->

 <link name="link_right_wheel">
        <inertial>
            <origin xyz="0 0 0" rpy="0 0 0"/>
            <mass value="1"/>
            <inertia ixx="0.0125" ixy="0" ixz="0" iyy="0.0125" iyz="0" izz="0.025"/>
        </inertial>
        <!-- Tires -->
        <visual>
            <origin xyz="0 0 0" rpy="1.5708 0 0"/> 
            <geometry>
                <cylinder length="0.03" radius="0.03125"/>
            </geometry>
            <material name="Red"/>
        </visual>
        <collision>
            <origin xyz="0 0 0" rpy="1.5708 0 0"/> 
            <geometry>
                <cylinder length="0.03" radius="0.03125"/>
            </geometry>
        </collision>
    </link>

  <!-- Caster Links -->

<!-- Front caster wheel joint -->
<joint name="joint_chassis_front_caster_wheel" type="fixed">
    <origin rpy="0 0 0" xyz="-0.1 0 -0.15" />
    <child link="link_front_caster_wheel" />
    <parent link="base_link" />
    <joint_properties damping="0.5" friction="0" />
</joint>

<!-- Front caster wheel link -->
<link name="link_front_caster_wheel">
    <inertial>
        <mass value="1" />
        <origin xyz="0 0 0" rpy="0 0 0" />
        <inertia ixx="0.002526666666667" ixy="0" ixz="0" iyy="0.002526666666667" iyz="0" izz="0.005"/>
    </inertial>

    <!-- Caster wheel support -->
    <collision>
        <origin rpy="0 0 0" xyz="0 0 0.00" />
        <geometry>
            <sphere radius="0.025" />
        </geometry>
    </collision>
    <visual>
        <origin rpy="0 0 0" xyz="0 0 0.00" />
        <geometry>
            <sphere radius="0.025" />
        </geometry>
        <material name="DarkBlue">
            <color rgba="0.2 0.2 0.4 1" />
        </material>
    </visual>

    <!-- Caster wheel -0.01875 -->
    <collision>
        <origin rpy="0 0 0" xyz="0 0 -0.01875" />
        <geometry>
            <sphere radius="0.0125" />
        </geometry>
    </collision>
    <visual>
        <origin rpy="0 0 0" xyz="0 0 -0.01875" />
        <geometry>
            <sphere radius="0.0125" />
        </geometry>
        <material name="Grey">
            <color rgba="0.6 0.6 0.6 1" />
        </material>
    </visual>
</link>

<!-- Back caster wheel joint -->
<joint name="joint_chassis_back_caster_wheel" type="fixed">
    <origin rpy="0 0 0" xyz="0.1 0 -0.15" />
    <child link="link_back_caster_wheel" />
    <parent link="base_link" />
    <joint_properties damping="1.0" friction="0" />
</joint>

<!-- Back caster wheel link -->
<link name="link_back_caster_wheel">
    <inertial>
        <mass value="1" />
        <origin xyz="0 0 0" rpy="0 0 0" />
        <inertia ixx="0.002526666666667" ixy="0" ixz="0" iyy="0.002526666666667" iyz="0" izz="0.005"/>
    </inertial>

    <!-- Caster wheel support -->
    <collision>
        <origin rpy="0 0 0" xyz="0 0 -0.00" />
        <geometry>
            <sphere radius="0.025" />
        </geometry>
    </collision>
    <visual>
        <origin rpy="0 0 0" xyz="0 0 -0.00" />
        <geometry>
            <sphere radius="0.025" />
        </geometry>
        <material name="DarkBlue">
            <color rgba="0.2 0.2 0.4 1" />
        </material>
    </visual>

    <!-- Caster wheel -->
    <collision>
        <origin rpy="0 0 0" xyz="0 0 -0.01875" />
        <geometry>
            <sphere radius="0.0125" />
        </geometry>
    </collision>
    <visual>
        <origin rpy="0 0 0" xyz="0 0 -0.01875" />
        <geometry>
            <sphere radius="0.0125" />
        </geometry>
        <material name="Grey">
            <color rgba="0.6 0.6 0.6 1" />
        </material>
    </visual>
</link>

<!-- Gazebo tags - Laser scan -->
<gazebo reference="joint_laser_scan_chassis">
    <preserveFixedJoint>true</preserveFixedJoint>
</gazebo>
<gazebo reference="link_laser_scan">
    <material>Gazebo/DarkGrey</material>
</gazebo>

<!-- Laser scan -->
<joint name="joint_laser_scan_chassis" type="fixed">
    <origin rpy="3.14159 0 0" xyz="0.25 0 0.075" /> <!-- Rotated 180 degrees in the x-axis -->
    <child link="link_laser_scan" />
    <parent link="base_link" />
    <joint_properties damping="1.0" friction="1.0" />
</joint>

<link name="link_laser_scan">
    <inertial>
        <origin xyz="0 0 0" rpy="0 0 0" />
        <mass value="0.5" />
        <inertia ixx="0.000252666666667" ixy="0" ixz="0" iyy="0.000252666666667" iyz="0" izz="0.0005"/>
    </inertial>
    <visual>
        <origin xyz="0 0 0" rpy="0 0 0" />
        <geometry>
            <cylinder radius="0.015" length="0.020"/>
        </geometry>
        <material name="Red">
            <color rgba="0.7 0.1 0.1 1" />
        </material>
    </visual>
    <collision>
        <origin xyz="0 0 0" rpy="0 0 0"/>
        <geometry>
            <cylinder radius="0.015" length="0.020"/>
        </geometry>
    </collision>
</link>


<!-- Laser Scanner Plugin -->
<gazebo reference="link_laser_scan">
    <sensor type="ray" name="head_hokuyo_sensor">
        <pose>0 0 0 0 0 0</pose>
        <visualize>true</visualize>
        <update_rate>20</update_rate>
        <ray>
            <scan>
                <horizontal>
                    <samples>720</samples>
                    <resolution>1</resolution>
                    <min_angle>-1.570796</min_angle>
                    <max_angle>1.570796</max_angle>
                </horizontal>
            </scan>
            <range>
                <min>0.020</min>
                <max>10.0</max>
                <resolution>0.01</resolution>
            </range>
            <noise>
                <type>gaussian</type>
                <mean>0.0</mean>
                <stddev>0.01</stddev>
            </noise>
        </ray>
        <plugin name="gazebo_ros_head_hokuyo_controller" filename="libgazebo_ros_laser.so">
            <topicName>/scan</topicName>
            <frameName>sensor_laser</frameName>
        </plugin>
    </sensor>
</gazebo>


<gazebo>
    <plugin filename="libgazebo_ros_diff_drive.so" name="differential_drive_controller">
        <!-- Always on -->
        <alwaysOn>true</alwaysOn>

        <!-- Update rate -->
        <updateRate>20.0</updateRate>

        <!-- Left and Right Wheel Joints -->
        <leftJoint>joint_chassis_left_wheel</leftJoint>
        <rightJoint>joint_chassis_right_wheel</rightJoint>

        <!-- Wheel properties -->
        <wheelSeparation>0.4</wheelSeparation>  <!-- This is an estimation. Adjust as per your design -->
        <wheelDiameter>0.0625</wheelDiameter>     <!-- Diameter of the wheels -->

        <!-- Speed Limits -->
        <maxWheelTorque>20</maxWheelTorque>      <!-- Maximum torque the wheels can apply -->
        <maxWheelAcceleration>5.0</maxWheelAcceleration>
        <maxSpeed>1.0</maxSpeed>                 <!-- Maximum speed in m/s -->
        <maxAngularSpeed>1.0</maxAngularSpeed>   <!-- Maximum rotational speed in rad/s -->

        <!-- ROS Topics -->
        <commandTopic>cmd_vel</commandTopic>     <!-- Topic to which the robot will listen for Twist messages -->
        <odometryTopic>odom</odometryTopic>      <!-- Topic where the robot will publish its odometry -->
        <odometryFrame>odom</odometryFrame>
        <robotBaseFrame>base_link</robotBaseFrame>  <!-- Change this if you have a different base frame -->

        <!-- Odometry Source -->
        <odometrySource>world</odometrySource>   <!-- Use 'world' for Gazebo based odometry. Change to 'encoder' if you have encoders simulated -->

        <!-- Other parameters (Optional) -->
        <publishWheelTF>true</publishWheelTF>
        <publishWheelJointState>true</publishWheelJointState>
        <publishTf>true</publishTf>
        <publishOdometryTf>true</publishOdometryTf>

    </plugin>
</gazebo>



</robot>